Workbook

Sheet 54500055018 SD 41
A1: PERIOD :,"01/01/2025 - 01/01/2025"," "," "," "," ","RELEASE DATE :","08/01/2025"
A2: ACCOUNT NO :,"545800055018 - IDR"," "," "," "," ","OPENING BALANCE :","1,525,903,335.80"
A3: ACCOUNT NAME :,"YAYASAN BINA PRESTASI INDONESIA GEMILANG"," "," "," "," ","CLOSING BALANCE :","1,599,538,335.80"
A4: TOTAL DEBIT :,"0.00","0.00"," "," "," ","LEDGER BALANCE :","2,355,097,324.80"
A5: TOTAL CREDIT :,"49.00","73,635,000.00"," "," "," ","AVAILABLE BALANCE :","2,355,097,324.80"
A8: ," ","Transaction History"
A9: Transaction Date,"Value Date","Reference No.","Cheque No.","Description","Debit","Credit","Balance"
A10: 45962 | B10: 0.23614583 | C10: 45962 | D10: '25110176001670204479 | F10: 079 - Transfer Masuk BI Fast (HERI PURNOMO/Spp november) VA 2555932242501107 MUHAMMAD MIKAEEL GIBRAN AVICENNA VA 2555932242501107 | G10: 0 | H10: 1540000 | I10: 4.0379228e+09
A11: 45962 | B11: 0.24511574 | C11: 45962 | D11: '25110176001621443294 | F11: 079 - Transfer Masuk BI Fast (AGA DESTIRA PAMUNGKAS/-) VA 2555932222301019 RABHYA FRIDAY ORLIN VA 2555932222301019 | G11: 0 | H11: 1400000 | I11: 4.0393228e+09
A12: 45962 | B12: 0.24648148 | C12: 45962 | D12: '25110176001101418531 | F12: 079 - Transfer Masuk BI Fast (PUTRI NINA ROKHMANIA/SPP Nov Rayvangga 6) VA 2555932202101047 RAYVANGGA PUTRA HARDIAN VA 2555932202101047 | G12: 0 | H12: 1400000 | I12: 4.0407228e+09
A13: 45962 | B13: 0.25466435 | C13: 45962 | D13: '25110176001731442703 | F13: 079 - Transfer Masuk BI Fast (EKO PRASETYO/Lainnya) VA 2555932202101023 KENZA MARITZA AURELIA VA 2555932202101023 | G13: 0 | H13: 1400000 | I13: 4.0421228e+09
A14: 45962 | B14: 0.25552083 | C14: 45962 | D14: '25110176001081442125 | F14: 079 - Transfer Masuk BI Fast (EKO PRASETYO/Lainnya) VA 2555932232401105 AQILLA SHEZA MAULIDA VA 2555932232401105 | G14: 0 | H14: 1450000 | I14: 4.0454728e+09
A15: 45962 | B15: 0.30782407 | C15: 45962 | D15: '25110176001571444261 | F15: 079 - Transfer Masuk BI Fast (ENJANG JATMIKA/) VA 2555932242501034 RAIQA PUTRI ADINDIKA VA 2555932242501034 | G15: 0 | H15: 1540000 | I15: 4.0501803e+09
A16: 45962 | B16: 0.30831019 | C16: 45962 | D16: '25110176001980235816 | F16: 079 - Transfer Masuk BI Fast (DOMPET ANAK BANGSA/GoPay Bank Transfer I) VA 2555932242501042 DELYSSA ASHADIYA MAHVEEN VA 2555932242501042 | G16: 0 | H16: 770000 | I16: 4.0509503e+09
A17: 45962 | B17: 0.32451389 | C17: 45962 | D17: '25110176000271444303 | F17: 079 - Transfer Masuk BI Fast (BIMA KAWINDRA/SPP Rei November 2025) VA 2555932212201002 NARENDRA KHAIRAN KAWINDRA VA 2555932212201002 | G17: 0 | H17: 1500000 | I17: 4.0555053e+09
A18: 45962 | B18: 0.32513889 | C18: 45962 | D18: '25110176001551444061 | F18: 079 - Transfer Masuk BI Fast (LAILI DWI INSYANI/SPP November Almahyra) VA 2555932242501003 ALMAHYRA QIRANI HERDIANTA VA 2555932242501003 | G18: 0 | H18: 1540000 | I18: 4.0570453e+09
A19: 45962 | B19: 0.32759259 | C19: 45962 | D19: '25110176000660813975 | F19: 079 - Transfer Masuk BI Fast (CANDRA PUTRA ARDI PR/KENSYAKIRA MADINAH) VA 2555932252601128 KENSYAKIRA NAMARA VA 2555932252601128 | G19: 0 | H19: 1617000 | I19: 4.0586623e+09
A20: 45962 | B20: 0.37118056 | C20: 45962 | D20: '25110188003540180340 | F20: 014 - Transfer Masuk VA 2555932212201099 DANISH FAUZA ANWAR 6420 008 9000014618723 SAIFUL ANWAR | G20: 0 | H20: 1400000 | I20: 4.0694073e+09
A21: 45962 | B21: 0.3990162 | C21: 45962 | D21: '25110176000230237292 | F21: 079 - Transfer Masuk BI Fast (YOLLANDA SUSANTI/Lainnya) VA 2555932222301003 ALIF HAZIQ SUNGKAR VA 2555932222301003 | G21: 0 | H21: 1400000 | I21: 4.0727323e+09
... A523: 45991 | B523: 0.970625 | C523: 45991 | D523: '25113076000360254451 | F523: 079 - Transfer Masuk BI Fast (FLIPTECH LENTERA INSPIRASI PERTIWI/FL100) VA 2555932252602189 SYDNEY SYARIFAH PUTRI BUDYANTORO VA 2555932252602189 | G523: 0 | H523: 1617000 | I523: 2.5941668e+09
A596: Saldo Awal | B596: 1.5259033e+09
A597: KREDIT
A598: Virtual Account | B598: =SUM(H10:H650) -> 816862500
A599: Non Virtual Account | B599: 0
A600: BUNGA | B600: 0
A601: DANA OPERASIONAL
A603: TOTAL | B603: =SUM(B598:B602) -> 816862500
A605: DEBIT
A607: FEE BILLER | B607: =SUM(D235:D282) -> 0
A608: BIAYA ADM | B608: 0
A609: DANA OPERASIONAL | B609: 0
A610: PAJAK | B610: 0
A611: RTGS FEE | B611: 0
A612: RTGS YAYASAN | B612: 0
A613: TOTAL | B613: =SUM(B607:B612) -> 0
A614: Saldo Akhir | B614: =B596+B603-B613 -> 2.3427658e+09
A615: Selisih | B615: =B614-I286 -> 4.6024531e+08

Sheet REALISASI
A1: YAYASAN PESANTREN ISLAM AL AZHAR
A2: REALISASI PENERIMAAN SDIA 41 KARAWANG
A3: TANGGAL 01-30 NOVEMBER 2025
A5: TAHUN PELAJARAN | B5: NIS | C5: NAMA LENGKAP | D5: SEKOLAH | E5: KELAS | F5: ASAL SEKOLAH | G5: URAIAN PEMBAYARAN | H5: REMARK | I5: REKENING KORAN | J5: TANGGAL BYAR | K5: WAKTU BAYAR | L5: TOTAL BAYAR | M5: BALANCING | N5: DONASI | O5: UANG PENDAFTARAN | P5: Uang Psikotest | Q5: Uang Test Kesehatan | R5: Uang Observasi | S5: Uang EKD | T5: Booking Fee | U5: UANG BUKU | V5: UANG PANGKAL | W5: UANG KEGIATAN | X5: UANG JAMIYYAH | Y5: UANG OSIS | Z5: DANA SYIAR | AA5: INFAQ MESJID | AB5: UANG SERAGAM | AC5: Uang Perlengkapan | AD5: Uang Kesehatan | AE5: UANG SEKOLAH | AF5: Daftar Ulang | AG5: Hutang | AH5: DISKON UANG PANGKAL | AI5: DISKON UANG SEKOLAH | AJ5: Refund | AK5: Dana Pembangunan | AL5: Dana Pendidikan | AM5: Dana Kegiatan | AN5: ATK | AO5: EKSKUL | AP5: UANG CATERING | AQ5: Uang Buku & ATK | AR5: Uang Buku | AS5: Uang Buku & Teknologi | AT5: Uang Pengembangan Pendidikan | AU5: Uang KBM | AV5: Antar Jemput | AW5: Uang Seragam Laki-laki | AX5: Uang Seragam Perempuan | AY5: Uang Tes Seleksi | AZ5: Asuransi | BA5: Uang Program Tahunan
C6: MUHAMMAD MIKAEEL GIBRAN AVICENNA | D6: SD Islam Al Azhar 41 Karawang | E6: =VLOOKUP(C6,KELAS!$A$2:$D$643,4,0) -> 2 MARWAH | H6: 079 - Transfer Masuk BI Fast (HERI PURNOMO/Spp november) VA 2555932242501107 MUHAMMAD MIKAEEL GIBRAN AVICENNA VA 2555932242501107 | I6: 1540000 | J6: 45962 | K6: 0.23614583 | L6: =SUM(N6:AP6) -> 0 | M6: =L6-I6 -> -1540000 | N6: 0 | O6: 0 | P6: 0 | Q6: 0 | R6: 0 | S6: 0 | T6: 0 | U6: 0 | V6: 0 | W6: 0 | X6: 0 | Y6: 0 | AA6: 0 | AB6: 0 | AC6: 0 | AD6: 0 | AE6: 0 | AF6: 0 | AG6: 0 | AH6: 0 | AI6: 0 | AJ6: 0 | AK6: 0 | AL6: 0 | AM6: 0 | AN6: 0 | AO6: 0 | AP6: 0 | AQ6: 0 | AR6: 0 | AS6: 0 | AT6: 0 | AU6: 0 | AV6: 0 | AW6: 0 | AX6: 0 | AY6: 0 | AZ6: 0 | BA6: 0
C7: RABHYA FRIDAY ORLIN | D7: SD Islam Al Azhar 41 Karawang | E7: =VLOOKUP(C7,KELAS!$A$2:$D$643,4,0) -> 4 MEKKAH | H7: 079 - Transfer Masuk BI Fast (AGA DESTIRA PAMUNGKAS/-) VA 2555932222301019 RABHYA FRIDAY ORLIN VA 2555932222301019 | I7: 1400000 | J7: 45962 | K7: 0.24511574 | L7: =SUM(N7:AP7) -> 0 | M7: =L7-I7 -> -1400000 | N7: 0 | O7: 0 | P7: 0 | Q7: 0 | R7: 0 | S7: 0 | T7: 0 | U7: 0 | V7: 0 | W7: 0 | X7: 0 | Y7: 0 | AA7: 0 | AB7: 0 | AC7: 0 | AD7: 0 | AE7: 0 | AF7: 0 | AG7: 0 | AH7: 0 | AI7: 0 | AJ7: 0 | AK7: 0 | AL7: 0 | AM7: 0 | AN7: 0 | AO7: 0 | AP7: 0 | AQ7: 0 | AR7: 0 | AS7: 0 | AT7: 0 | AU7: 0 | AV7: 0 | AW7: 0 | AX7: 0 | AY7: 0 | AZ7: 0 | BA7: 0
C8: RAYVANGGA PUTRA HARDIAN | D8: SD Islam Al Azhar 41 Karawang | E8: =VLOOKUP(C8,KELAS!$A$2:$D$643,4,0) -> 6 MINA | H8: 079 - Transfer Masuk BI Fast (PUTRI NINA ROKHMANIA/SPP Nov Rayvangga 6) VA 2555932202101047 RAYVANGGA PUTRA HARDIAN VA 2555932202101047 | I8: 1400000 | J8: 45962 | K8: 0.24648148 | L8: =SUM(N8:AP8) -> 0 | M8: =L8-I8 -> -1400000 | N8: 0 | O8: 0 | P8: 0 | Q8: 0 | R8: 0 | S8: 0 | T8: 0 | U8: 0 | V8: 0 | W8: 0 | X8: 0 | Y8: 0 | AA8: 0 | AB8: 0 | AC8: 0 | AD8: 0 | AE8: 0 | AF8: 0 | AG8: 0 | AH8: 0 | AI8: 0 | AJ8: 0 | AK8: 0 | AL8: 0 | AM8: 0 | AN8: 0 | AO8: 0 | AP8: 0 | AQ8: 0 | AR8: 0 | AS8: 0 | AT8: 0 | AU8: 0 | AV8: 0 | AW8: 0 | AX8: 0 | AY8: 0 | AZ8: 0 | BA8: 0
C9: KENZA MARITZA AURELIA | D9: SD Islam Al Azhar 41 Karawang | E9: =VLOOKUP(C9,KELAS!$A$2:$D$643,4,0) -> 6 MEKKAH | H9: 079 - Transfer Masuk BI Fast (EKO PRASETYO/Lainnya) VA 2555932202101023 KENZA MARITZA AURELIA VA 2555932202101023 | I9: 1400000 | J9: 45962 | K9: 0.25466435 | L9: =SUM(N9:AP9) -> 0 | M9: =L9-I9 -> -1400000 | N9: 0 | O9: 0 | P9: 0 | Q9: 0 | R9: 0 | S9: 0 | T9: 0 | U9: 0 | V9: 0 | W9: 0 | X9: 0 | Y9: 0 | AA9: 0 | AB9: 0 | AC9: 0 | AD9: 0 | AE9: 0 | AF9: 0 | AG9: 0 | AH9: 0 | AI9: 0 | AJ9: 0 | AK9: 0 | AL9: 0 | AM9: 0 | AN9: 0 | AO9: 0 | AP9: 0 | AQ9: 0 | AR9: 0 | AS9: 0 | AT9: 0 | AU9: 0 | AV9: 0 | AW9: 0 | AX9: 0 | AY9: 0 | AZ9: 0 | BA9: 0
C10: AQILLA SHEZA MAULIDA | D10: SD Islam Al Azhar 41 Karawang | E10: =VLOOKUP(C10,KELAS!$A$2:$D$643,4,0) -> 3 MADINAH | H10: 079 - Transfer Masuk BI Fast (EKO PRASETYO/Lainnya) VA 2555932232401105 AQILLA SHEZA MAULIDA VA 2555932232401105 | I10: 1450000 | J10: 45962 | K10: 0.25552083 | L10: =SUM(N10:AP10) -> 0 | M10: =L10-I10 -> -1450000 | N10: 0 | O10: 0 | P10: 0 | Q10: 0 | R10: 0 | S10: 0 | T10: 0 | U10: 0 | V10: 0 | W10: 0 | X10: 0 | Y10: 0 | AA10: 0 | AB10: 0 | AC10: 0 | AD10: 0 | AE10: 0 | AF10: 0 | AG10: 0 | AH10: 0 | AI10: 0 | AJ10: 0 | AK10: 0 | AL10: 0 | AM10: 0 | AN10: 0 | AO10: 0 | AP10: 0 | AQ10: 0 | AR10: 0 | AS10: 0 | AT10: 0 | AU10: 0 | AV10: 0 | AW10: 0 | AX10: 0 | AY10: 0 | AZ10: 0 | BA10: 0
C11: RAIQA PUTRI ADINDIKA | D11: SD Islam Al Azhar 41 Karawang | E11: =VLOOKUP(C11,KELAS!$A$2:$D$643,4,0) -> 2 MARWAH | H11: 079 - Transfer Masuk BI Fast (ENJANG JATMIKA/) VA 2555932242501034 RAIQA PUTRI ADINDIKA VA 2555932242501034 | I11: 1540000 | J11: 45962 | K11: 0.30782407 | L11: =SUM(N11:AP11) -> 0 | M11: =L11-I11 -> -1540000 | N11: 0 | O11: 0 | P11: 0 | Q11: 0 | R11: 0 | S11: 0 | T11: 0 | U11: 0 | V11: 0 | W11: 0 | X11: 0 | Y11: 0 | AA11: 0 | AB11: 0 | AC11: 0 | AD11: 0 | AE11: 0 | AF11: 0 | AG11: 0 | AH11: 0 | AI11: 0 | AJ11: 0 | AK11: 0 | AL11: 0 | AM11: 0 | AN11: 0 | AO11: 0 | AP11: 0 | AQ11: 0 | AR11: 0 | AS11: 0 | AT11: 0 | AU11: 0 | AV11: 0 | AW11: 0 | AX11: 0 | AY11: 0 | AZ11: 0 | BA11: 0
C12: DELYSSA ASHADIYA MAHVEEN | D12: SD Islam Al Azhar 41 Karawang | E12: =VLOOKUP(C12,KELAS!$A$2:$D$643,4,0) -> 2 MEKKAH | H12: 079 - Transfer Masuk BI Fast (DOMPET ANAK BANGSA/GoPay Bank Transfer I) VA 2555932242501042 DELYSSA ASHADIYA MAHVEEN VA 2555932242501042 | I12: 770000 | J12: 45962 | K12: 0.30831019 | L12: =SUM(N12:AP12) -> 0 | M12: =L12-I12 -> -770000 | N12: 0 | O12: 0 | P12: 0 | Q12: 0 | R12: 0 | S12: 0 | T12: 0 | U12: 0 | V12: 0 | W12: 0 | X12: 0 | Y12: 0 | AA12: 0 | AB12: 0 | AC12: 0 | AD12: 0 | AE12: 0 | AF12: 0 | AG12: 0 | AH12: 0 | AI12: 0 | AJ12: 0 | AK12: 0 | AL12: 0 | AM12: 0 | AN12: 0 | AO12: 0 | AP12: 0 | AQ12: 0 | AR12: 0 | AS12: 0 | AT12: 0 | AU12: 0 | AV12: 0 | AW12: 0 | AX12: 0 | AY12: 0 | AZ12: 0 | BA12: 0
C13: NARENDRA KHAIRAN KAWINDRA | D13: SD Islam Al Azhar 41 Karawang | E13: =VLOOKUP(C13,KELAS!$A$2:$D$643,4,0) -> 5 MEKKAH | H13: 079 - Transfer Masuk BI Fast (BIMA KAWINDRA/SPP Rei November 2025) VA 2555932212201002 NARENDRA KHAIRAN KAWINDRA VA 2555932212201002 | I13: 1500000 | J13: 45962 | K13: 0.32451389 | L13: =SUM(N13:AP13) -> 0 | M13: =L13-I13 -> -1500000 | N13: 0 | O13: 0 | P13: 0 | Q13: 0 | R13: 0 | S13: 0 | T13: 0 | U13: 0 | V13: 0 | W13: 0 | X13: 0 | Y13: 0 | AA13: 0 | AB13: 0 | AC13: 0 | AD13: 0 | AE13: 0 | AF13: 0 | AG13: 0 | AH13: 0 | AI13: 0 | AJ13: 0 | AK13: 0 | AL13: 0 | AM13: 0 | AN13: 0 | AO13: 0 | AP13: 0 | AQ13: 0 | AR13: 0 | AS13: 0 | AT13: 0 | AU13: 0 | AV13: 0 | AW13: 0 | AX13: 0 | AY13: 0 | AZ13: 0 | BA13: 0
C14: ALMAHYRA QIRANI HERDIANTA | D14: SD Islam Al Azhar 41 Karawang | E14: =VLOOKUP(C14,KELAS!$A$2:$D$643,4,0) -> 2 MADINAH | H14: 079 - Transfer Masuk BI Fast (LAILI DWI INSYANI/SPP November Almahyra) VA 2555932242501003 ALMAHYRA QIRANI HERDIANTA VA 2555932242501003 | I14: 1540000 | J14: 45962 | K14: 0.32513889 | L14: =SUM(N14:AP14) -> 0 | M14: =L14-I14 -> -1540000 | N14: 0 | O14: 0 | P14: 0 | Q14: 0 | R14: 0 | S14: 0 | T14: 0 | U14: 0 | V14: 0 | W14: 0 | X14: 0 | Y14: 0 | AA14: 0 | AB14: 0 | AC14: 0 | AD14: 0 | AE14: 0 | AF14: 0 | AG14: 0 | AH14: 0 | AI14: 0 | AJ14: 0 | AK14: 0 | AL14: 0 | AM14: 0 | AN14: 0 | AO14: 0 | AP14: 0 | AQ14: 0 | AR14: 0 | AS14: 0 | AT14: 0 | AU14: 0 | AV14: 0 | AW14: 0 | AX14: 0 | AY14: 0 | AZ14: 0 | BA14: 0
C15: KENSYAKIRA NAMARA | D15: SD Islam Al Azhar 41 Karawang | E15: =VLOOKUP(C15,KELAS!$A$2:$D$643,4,0) -> 1 MADINAH | H15: 079 - Transfer Masuk BI Fast (CANDRA PUTRA ARDI PR/KENSYAKIRA MADINAH) VA 2555932252601128 KENSYAKIRA NAMARA VA 2555932252601128 | I15: 1617000 | J15: 45962 | K15: 0.32759259 | L15: =SUM(N15:AP15) -> 0 | M15: =L15-I15 -> -1617000 | N15: 0 | O15: 0 | P15: 0 | Q15: 0 | R15: 0 | S15: 0 | T15: 0 | U15: 0 | V15: 0 | W15: 0 | X15: 0 | Y15: 0 | AA15: 0 | AB15: 0 | AC15: 0 | AD15: 0 | AE15: 0 | AF15: 0 | AG15: 0 | AH15: 0 | AI15: 0 | AJ15: 0 | AK15: 0 | AL15: 0 | AM15: 0 | AN15: 0 | AO15: 0 | AP15: 0
C16: DANISH FAUZA ANWAR | D16: SD Islam Al Azhar 41 Karawang | E16: =VLOOKUP(C16,KELAS!$A$2:$D$643,4,0) -> 5 MEKKAH | H16: 014 - Transfer Masuk VA 2555932212201099 DANISH FAUZA ANWAR 6420 008 9000014618723 SAIFUL ANWAR | I16: 1400000 | J16: 45962 | K16: 0.37118056 | L16: =SUM(N16:AP16) -> 0 | M16: =L16-I16 -> -1400000 | N16: 0 | O16: 0 | P16: 0 | Q16: 0 | R16: 0 | S16: 0 | T16: 0 | U16: 0 | V16: 0 | W16: 0 | X16: 0 | Y16: 0 | AA16: 0 | AB16: 0 | AC16: 0 | AD16: 0 | AE16: 0 | AF16: 0 | AG16: 0 | AH16: 0 | AI16: 0 | AJ16: 0 | AK16: 0 | AL16: 0 | AM16: 0 | AN16: 0 | AO16: 0 | AP16: 0
C17: ALIF HAZIQ SUNGKAR | D17: SD Islam Al Azhar 41 Karawang | E17: =VLOOKUP(C17,KELAS!$A$2:$D$643,4,0) -> 4 MEKKAH | H17: 079 - Transfer Masuk BI Fast (YOLLANDA SUSANTI/Lainnya) VA 2555932222301003 ALIF HAZIQ SUNGKAR VA 2555932222301003 | I17: 1400000 | J17: 45962 | K17: 0.3990162 | L17: =SUM(N17:AP17) -> 0 | M17: =L17-I17 -> -1400000 | N17: 0 | O17: 0 | P17: 0 | Q17: 0 | R17: 0 | S17: 0 | T17: 0 | U17: 0 | V17: 0 | W17: 0 | X17: 0 | Y17: 0 | AA17: 0 | AB17: 0 | AC17: 0 | AD17: 0 | AE17: 0 | AF17: 0 | AG17: 0 | AH17: 0 | AI17: 0 | AJ17: 0 | AK17: 0 | AL17: 0 | AM17: 0 | AN17: 0 | AO17: 0 | AP17: 0
C18: SAQEENARAVA LASHIRA ALIREDJA | D18: SD Islam Al Azhar 41 Karawang | E18: =VLOOKUP(C18,KELAS!$A$2:$D$643,4,0) -> 1 MINA | H18: 079 - Transfer Masuk BI Fast (EVI PRIYANTI/Spp September 2025) VA 2555932252601041 SAQEENARAVA LASHIRA ALIREDJA VA 2555932252601041 | I18: 1617000 | J18: 45962 | K18: 0.41140046 | L18: =SUM(N18:AP18) -> 0 | M18: =L18-I18 -> -1617000 | N18: 0 | O18: 0 | P18: 0 | Q18: 0 | R18: 0 | S18: 0 | T18: 0 | U18: 0 | V18: 0 | W18: 0 | X18: 0 | Y18: 0 | AA18: 0 | AB18: 0 | AC18: 0 | AD18: 0 | AE18: 0 | AF18: 0 | AG18: 0 | AH18: 0 | AI18: 0 | AJ18: 0 | AK18: 0 | AL18: 0 | AM18: 0 | AN18: 0 | AO18: 0 | AP18: 0
C19: MAIZA RAFANIA KHAIREEN HARAHAP | D19: SD Islam Al Azhar 41 Karawang | E19: =VLOOKUP(C19,KELAS!$A$2:$D$643,4,0) -> 1 MINA | H19: 079 - Transfer Masuk BI Fast (KHARINA YUFIN PUTRI/Maiza 1 mina) VA 2555932252601184 MAIZA RAFANIA KHAIREEN HARAHAP VA 2555932252601184 | I19: 1617000 | J19: 45962 | K19: 0.42386574 | L19: =SUM(N19:AP19) -> 0 | M19: =L19-I19 -> -1617000 | N19: 0 | O19: 0 | P19: 0 | Q19: 0 | R19: 0 | S19: 0 | T19: 0 | U19: 0 | V19: 0 | W19: 0 | X19: 0 | Y19: 0 | AA19: 0 | AB19: 0 | AC19: 0 | AD19: 0 | AE19: 0 | AF19: 0 | AG19: 0 | AH19: 0 | AI19: 0 | AJ19: 0 | AK19: 0 | AL19: 0 | AM19: 0 | AN19: 0 | AO19: 0 | AP19: 0
C20: ALMEERA QAIREEN CASSIMIRA REANDA | D20: SD Islam Al Azhar 41 Karawang | E20: =VLOOKUP(C20,KELAS!$A$2:$D$643,4,0) -> 3 MINA | H20: 079 - Transfer Masuk BI Fast (DEWI FAJAR KESU/) VA 2555932232401028 ALMEERA QAIREEN CASSIMIRA REANDA VA 2555932232401028 | I20: 1400000 | J20: 45962 | K20: 0.44112269 | L20: =SUM(N20:AP20) -> 0 | M20: =L20-I20 -> -1400000 | N20: 0 | O20: 0 | P20: 0 | Q20: 0 | R20: 0 | S20: 0 | T20: 0 | U20: 0 | V20: 0 | W20: 0 | X20: 0 | Y20: 0 | AA20: 0 | AB20: 0 | AC20: 0 | AD20: 0 | AE20: 0 | AF20: 0 | AG20: 0 | AH20: 0 | AI20: 0 | AJ20: 0 | AK20: 0 | AL20: 0 | AM20: 0 | AN20: 0 | AO20: 0 | AP20: 0
C21: ZIANKA SHAKILA PUTRI WAHYUDI | D21: SD Islam Al Azhar 41 Karawang | E21: =VLOOKUP(C21,KELAS!$A$2:$D$643,4,0) -> 1 MARWAH/TAHFIDZ | H21: 014 - Transfer Masuk VA 2555932252601151 ZIANKA SHAKILA PUTRI WAHYUDI 9330 535 446000004010 ShopeePay | I21: 1617000 | J21: 45962 | K21: 0.44297454 | L21: =SUM(N21:AP21) -> 0 | M21: =L21-I21 -> -1617000 | N21: 0 | O21: 0 | P21: 0 | Q21: 0 | R21: 0 | S21: 0 | T21: 0 | U21: 0 | V21: 0 | W21: 0 | X21: 0 | Y21: 0 | AA21: 0 | AB21: 0 | AC21: 0 | AD21: 0 | AE21: 0 | AF21: 0 | AG21: 0 | AH21: 0 | AI21: 0 | AJ21: 0 | AK21: 0 | AL21: 0 | AM21: 0 | AN21: 0 | AO21: 0 | AP21: 0
C22: DIZA NOUMIRA HANIFA | D22: SD Islam Al Azhar 41 Karawang | E22: =VLOOKUP(C22,KELAS!$A$2:$D$643,4,0) -> 3 MARWAH | H22: 079 - Transfer Masuk BI Fast (HERI SETIAWAN/-) VA 2555932232401024 DIZA NOUMIRA HANIFA VA 2555932232401024 | I22: 1400000 | J22: 45962 | K22: 0.45283565 | L22: =SUM(N22:AP22) -> 0 | M22: =L22-I22 -> -1400000 | N22: 0 | O22: 0 | P22: 0 | Q22: 0 | R22: 0 | S22: 0 | T22: 0 | U22: 0 | V22: 0 | W22: 0 | X22: 0 | Y22: 0 | AA22: 0 | AB22: 0 | AC22: 0 | AD22: 0 | AE22: 0 | AF22: 0 | AG22: 0 | AH22: 0 | AI22: 0 | AJ22: 0 | AK22: 0 | AL22: 0 | AM22: 0 | AN22: 0 | AO22: 0 | AP22: 0
C23: ALULA ABELIA | D23: SD Islam Al Azhar 41 Karawang | E23: =VLOOKUP(C23,KELAS!$A$2:$D$643,4,0) -> 5 MEKKAH | H23: 079 - Transfer Masuk BI Fast (INDAH NURJANAH/Alula spp novmber) VA 2555932212201003 ALULA ABELIA VA 2555932212201003 | I23: 1400000 | J23: 45962 | K23: 0.45725694 | L23: =SUM(N23:AP23) -> 0 | M23: =L23-I23 -> -1400000 | N23: 0 | O23: 0 | P23: 0 | Q23: 0 | R23: 0 | S23: 0 | T23: 0 | U23: 0 | V23: 0 | W23: 0 | X23: 0 | Y23: 0 | AA23: 0 | AB23: 0 | AC23: 0 | AD23: 0 | AE23: 0 | AF23: 0 | AG23: 0 | AH23: 0 | AI23: 0 | AJ23: 0 | AK23: 0 | AL23: 0 | AM23: 0 | AN23: 0 | AO23: 0 | AP23: 0
C24: KANAYA REINA DEWI | D24: SD Islam Al Azhar 41 Karawang | E24: =VLOOKUP(C24,KELAS!$A$2:$D$643,4,0) -> 4 MEKKAH | H24: 079 - Transfer Masuk BI Fast (CATUR RAHARJO/-) VA 2555932222301142 KANAYA REINA DEWI VA 2555932222301142 | I24: 1450000 | J24: 45962 | K24: 0.46011574 | L24: =SUM(N24:AP24) -> 0 | M24: =L24-I24 -> -1450000 | N24: 0 | O24: 0 | P24: 0 | Q24: 0 | R24: 0 | S24: 0 | T24: 0 | U24: 0 | V24: 0 | W24: 0 | X24: 0 | Y24: 0 | AA24: 0 | AB24: 0 | AC24: 0 | AD24: 0 | AE24: 0 | AF24: 0 | AG24: 0 | AH24: 0 | AI24: 0 | AJ24: 0 | AK24: 0 | AL24: 0 | AM24: 0 | AN24: 0 | AO24: 0 | AP24: 0
C25: MUHAMMAD RAFIF SHIDDIQ SETIADI | D25: SD Islam Al Azhar 41 Karawang | E25: =VLOOKUP(C25,KELAS!$A$2:$D$643,4,0) -> 2 MADINAH | H25: 079 - Transfer Masuk BI Fast (dr DARA MUSTIKA DEWI/) VA 2555932242501174 MUHAMMAD RAFIF SHIDDIQ SETIADI VA 2555932242501174 | I25: 1540000 | J25: 45962 | K25: 0.47587963 | L25: =SUM(N25:AP25) -> 0 | M25: =L25-I25 -> -1540000 | N25: 0 | O25: 0 | P25: 0 | Q25: 0 | R25: 0 | S25: 0 | T25: 0 | U25: 0 | V25: 0 | W25: 0 | X25: 0 | Y25: 0 | AA25: 0 | AB25: 0 | AC25: 0 | AD25: 0 | AE25: 0 | AF25: 0 | AG25: 0 | AH25: 0 | AI25: 0 | AJ25: 0 | AK25: 0 | AL25: 0 | AM25: 0 | AN25: 0 | AO25: 0 | AP25: 0
C26: GHANI RASYID SUHENDRA | D26: SD Islam Al Azhar 41 Karawang | E26: =VLOOKUP(C26,KELAS!$A$2:$D$643,4,0) -> 4 MEKKAH | H26: 079 - Transfer Masuk BI Fast (NURLEILY/Spp Ghani) VA 2555932222301158 GHANI RASYID SUHENDRA VA 2555932222301158 | I26: 1450000 | J26: 45962 | K26: 0.48251157 | L26: =SUM(N26:AP26) -> 0 | M26: =L26-I26 -> -1450000 | N26: 0 | O26: 0 | P26: 0 | Q26: 0 | R26: 0 | S26: 0 | T26: 0 | U26: 0 | V26: 0 | W26: 0 | X26: 0 | Y26: 0 | AA26: 0 | AB26: 0 | AC26: 0 | AD26: 0 | AE26: 0 | AF26: 0 | AG26: 0 | AH26: 0 | AI26: 0 | AJ26: 0 | AK26: 0 | AL26: 0 | AM26: 0 | AN26: 0 | AO26: 0 | AP26: 0
... C159: ATHIRA JANNAH PRASOJO | D159: SD Islam Al Azhar 41 Karawang | E159: =VLOOKUP(C159,KELAS!$A$2:$D$643,4,0) -> 1 MARWAH/TAHFIDZ | H159: 079 - Transfer Masuk BI Fast (LUQMAN HABIEB PRASOJ/Payment) VA 2555932252601013 ATHIRA JANNAH PRASOJO VA 2555932252601013 | I159: 1617000 | J159: 45966 | K159: 0.47413194 | L159: =SUM(N159:AP159) -> 0 | M159: =L159-I159 -> -1617000 | N159: 0 | O159: 0 | P159: 0 | Q159: 0 | R159: 0 | S159: 0 | T159: 0 | U159: 0 | V159: 0 | W159: 0 | X159: 0 | Y159: 0 | AA159: 0 | AB159: 0 | AC159: 0 | AD159: 0 | AE159: 0 | AF159: 0 | AG159: 0 | AH159: 0 | AI159: 0 | AJ159: 0 | AK159: 0 | AL159: 0 | AM159: 0 | AN159: 0 | AO159: 0 | AP159: 0
C160: MIKAIL FAYYADH PRASOJO | D160: SD Islam Al Azhar 41 Karawang | E160: =VLOOKUP(C160,KELAS!$A$2:$D$643,4,0) -> 3 MADINAH | H160: 079 - Transfer Masuk BI Fast (LUQMAN HABIEB PRASOJ/Payment) VA 2555932232401012 MIKAIL FAYYADH PRASOJO VA 2555932232401012 | I160: 1400000 | J160: 45966 | K160: 0.47447917 | L160: =SUM(N160:AP160) -> 0 | M160: =L160-I160 -> -1400000
C161: KIREI VELANDRA RUSMIANTO | D161: SD Islam Al Azhar 41 Karawang | E161: =VLOOKUP(C161,KELAS!$A$2:$D$643,4,0) -> 1 MADINAH | H161: 079 - Transfer Masuk BI Fast (PUTRI NURHAJIZAH/) VA 2555932252601031 KIREI VELANDRA RUSMIANTO VA 2555932252601031 | I161: 1540000 | J161: 45966 | K161: 0.50150463 | L161: =SUM(N161:AP161) -> 0 | M161: =L161-I161 -> -1540000
C162: MOANA ZEIN | D162: SD Islam Al Azhar 41 Karawang | E162: =VLOOKUP(C162,KELAS!$A$2:$D$643,4,0) -> 3 MARWAH | H162: 079 - Transfer Masuk BI Fast (TOSHIYUKI ASAHINO/Transfer ke YAYASAN BI) VA 2555932232401005 MOANA ZEIN VA 2555932232401005 | I162: 1400000 | J162: 45966 | K162: 0.54280093 | L162: =SUM(N162:AP162) -> 0 | M162: =L162-I162 -> -1400000
C163: SARAISHA SAKINA ABDULLAH | D163: SD Islam Al Azhar 41 Karawang | E163: =VLOOKUP(C163,KELAS!$A$2:$D$643,4,0) -> 4 MEKKAH | H163: 079 - Transfer Masuk BI Fast (FLIPTECH LENTERA INSPIRASI PERTIWI/SPP S) VA 2555932222301023 SARAISHA SAKINA ABDULLAH VA 2555932222301023 | I163: 1400000 | J163: 45966 | K163: 0.55751157 | L163: =SUM(N163:AP163) -> 0 | M163: =L163-I163 -> -1400000
C164: GANENDRA FATHA ARFADHYA | D164: SD Islam Al Azhar 41 Karawang | E164: =VLOOKUP(C164,KELAS!$A$2:$D$643,4,0) -> 2 MEKKAH | H164: 014 - Transfer Masuk VA 2555932242501153 GANENDRA FATHA ARFADHYA 3388 451 7177223098 HILMAN RAMDHANI | I164: 1540000 | J164: 45966 | K164: 0.57373843 | L164: =SUM(N164:AP164) -> 0 | M164: =L164-I164 -> -1540000
C165: KEI KHUMAIRAH CHOIRUL | D165: SD Islam Al Azhar 41 Karawang | E165: =VLOOKUP(C165,KELAS!$A$2:$D$643,4,0) -> 3 MADINAH | H165: 079 - Transfer Masuk BI Fast (AKHMAD BAHTIAR/an Kei Khumairah Choirul) VA 2555932232401036 KEI KHUMAIRAH CHOIRUL VA 2555932232401036 | I165: 2800000 | J165: 45966 | K165: 0.62717593 | L165: =SUM(N165:AP165) -> 0 | M165: =L165-I165 -> -2800000
C166: Muhammad Al Fatih Choirul | D166: SD Islam Al Azhar 41 Karawang | E166: =VLOOKUP(C166,KELAS!$A$2:$D$643,4,0) -> 6 MINA | H166: 079 - Transfer Masuk BI Fast (AKHMAD BAHTIAR/an Muhammad Ali Fatih Cho) VA 2555932202101061 Muhammad Al Fatih Choirul VA 2555932202101061 | I166: 2800000 | J166: 45966 | K166: 0.6287037 | L166: =SUM(N166:AP166) -> 0 | M166: =L166-I166 -> -2800000
C167: AQILLA FEISYA PUTRI ANINDITA | D167: SD Islam Al Azhar 41 Karawang | E167: =VLOOKUP(C167,KELAS!$A$2:$D$643,4,0) -> 6 MADINAH | H167: 079 - Transfer Masuk BI Fast (ISNIASITA DITIA/) VA 2555932202101036 AQILLA FEISYA PUTRI ANINDITA VA 2555932202101036 | I167: 1400000 | J167: 45966 | K167: 0.65810185 | L167: =SUM(N167:AP167) -> 0 | M167: =L167-I167 -> -1400000
C168: DIRGAHAYU ARJUNA PASHA | D168: SD Islam Al Azhar 41 Karawang | E168: =VLOOKUP(C168,KELAS!$A$2:$D$643,4,0) -> 4 MEKKAH | H168: 079 - Transfer Masuk BI Fast (FEMTINE WIRDITIANI DRG/Spp bulan okt) VA 2555932222301172 DIRGAHAYU ARJUNA PASHA VA 2555932222301172 | I168: 1450000 | J168: 45966 | K168: 0.68918981 | L168: =SUM(N168:AP168) -> 0 | M168: =L168-I168 -> -1450000
C169: ATAYA RAFIQ AKBAR | D169: SD Islam Al Azhar 41 Karawang | E169: =VLOOKUP(C169,KELAS!$A$2:$D$643,4,0) -> 4 MINA | H169: 079 - Transfer Masuk BI Fast (MIRA SALFANI S/) VA 2555932222301017 ATAYA RAFIQ AKBAR VA 2555932222301017 | I169: 1400000 | J169: 45966 | K169: 0.71728009 | L169: =SUM(N169:AP169) -> 0 | M169: =L169-I169 -> -1400000
C170: DELLANO ALBY NARESHWARA | D170: SD Islam Al Azhar 41 Karawang | E170: =VLOOKUP(C170,KELAS!$A$2:$D$643,4,0) -> 2 MINA | H170: 079 - Transfer Masuk BI Fast (Dian Andi Nastiti/Spp nov 2025 - dellano) VA 2555932242501106 DELLANO ALBY NARESHWARA VA 2555932242501106 | I170: 1540000 | J170: 45966 | K170: 0.76386574 | L170: =SUM(N170:AP170) -> 0 | M170: =L170-I170 -> -1540000
C171: ADAM ALDEBARAN MULYA PRAKASA | D171: SD Islam Al Azhar 41 Karawang | E171: =VLOOKUP(C171,KELAS!$A$2:$D$643,4,0) -> 2 MINA | H171: 079 - Transfer Masuk BI Fast (SEPTIAN DENES PRAKASA/-) VA 2555932242501110 ADAM ALDEBARAN MULYA PRAKASA VA 2555932242501110 | I171: 1550000 | J171: 45966 | K171: 0.78200231 | L171: =SUM(N171:AP171) -> 0 | M171: =L171-I171 -> -1550000
... C519: SYDNEY SYARIFAH PUTRI BUDYANTORO | D519: SD Islam Al Azhar 41 Karawang | E519: =VLOOKUP(C519,KELAS!$A$2:$D$643,4,0) -> #N/A | H519: 079 - Transfer Masuk BI Fast (FLIPTECH LENTERA INSPIRASI PERTIWI/FL100) VA 2555932252602189 SYDNEY SYARIFAH PUTRI BUDYANTORO VA 2555932252602189 | I519: 1617000 | J519: 45991 | K519: 0.970625 | L519: =SUM(N519:AP519) -> 0 | M519: =L519-I519 -> -1617000
D520: SD Islam Al Azhar 41 Karawang | E520: =VLOOKUP(C520,KELAS!$A$2:$D$643,4,0) -> #N/A | L520: =SUM(N520:AP520) -> 0 | M520: =L520-I520 -> 0
...

Sheet KELAS
A1: NAMA MURID | B1: L/P | C1: NAMA PANGGILAN | D1: KELAS
A2: ADIKA ZAYYAN RINALDI | B2: L | C2: ADIKA | D2: 1 MEKKAH
A3: ADREENA AZKADINA MAULANA | B3: P | C3: ADREENA | D3: 1 MEKKAH
A4: ALAMANDA HAURA RABBANI | B4: P | C4: MANDA | D4: 1 MEKKAH
A5: ALEYZA QAIREEN MUFID | B5: P | C5: QAIREEN | D5: 1 MEKKAH
A6: ALISHA SHAFIYYAH QADIRINA | B6: P | C6: ALISHA | D6: 1 MEKKAH
A7: ANDHISYA AQILA PUTRI | B7: P | C7: DHISYA | D7: 1 MEKKAH
A8: ARCELLO KAIHARVARD AL GHAIZAN | B8: L | C8: ARCELLO | D8: 1 MEKKAH
A9: ARSAKHA ADIABBAD | B9: L | C9: SAKHA | D9: 1 MEKKAH
A10: AYANADHIRA QANITA | B10: P | C10: AYA | D10: 1 MEKKAH
A11: AZKIA FARANISA DEWI | B11: P | C11: AZKIA | D11: 1 MEKKAH
A12: BEBBY SABRINA | B12: P | C12: BEBI | D12: 1 MEKKAH
... A338: ZAFINA NURUL AISYAH | B338: P | C338: ZAFINA | D338: 3 MINA
A339: ARSHAKA ZHAFRAN AL KHALIFA | D339: 3 MINA
A340: AALIYAH SYAHIDA AZ-ZAHRA | B340: P | C340: ALIYAH | D340: 3 MARWAH
A341: ABINAYA JUN PRAKOSO | B341: L | C341: ABIN | D341: 3 MARWAH
A342: AINAYYA SHEEHAN LASHIRA | B342: P | C342: AINAYYA | D342: 3 MARWAH
A343: ALFATHAN PUTRA AGIYASA | B343: L | C343: FATHAN | D343: 3 MARWAH
A344: ALMEER AHMED AL FATIH | B344: L | C344: ALMEER | D344: 3 MARWAH
A345: AMARA HANUM ARDIYANTI | B345: P | C345: AMARA | D345: 3 MARWAH
A346: AMIRAH TSABITA AZ ZAHRA | B346: P | C346: ABHIA | D346: 3 MARWAH
A347: AQLAN ARSHAKA NANDANA | B347: L | C347: ARSHAKA | D347: 3 MARWAH
A348: DAFFA AZKARYA WIBOWO | B348: L | C348: DAFFA | D348: 3 MARWAH
A349: DIZA NOUMIRA HANIFA | B349: P | C349: DIZA | D349: 3 MARWAH
A350: GIBRAN MAHESWARA ARYASATYA | B350: L | C350: GIBRAN | D350: 3 MARWAH
A351: IFTITAH KHAERUNNISA MEGEN | B351: P | C351: IFTITAH | D351: 3 MARWAH
... A643: ZAKIAH KIREYNAHIKARI SETIOKO | B643: P | C643: KIA | D643: 6 MINA
